<?xml version="1.0" ?>
<robot name="AMR" xmlns:xacro="http://www.ros.org/wiki/xacro">

<xacro:include filename="$(find AMR_description)/urdf/materials.xacro" />
<xacro:include filename="$(find AMR_description)/urdf/AMR.trans" />
<xacro:include filename="$(find AMR_description)/urdf/AMR.gazebo" />
<link name="base_link">
  <inertial>
    <origin xyz="0.01897877889872416 0.0503794465577817 0.029670984969818247" rpy="0 0 0"/>
    <mass value="1.6562310340355082"/>
    <inertia ixx="0.00156" iyy="0.000667" izz="0.001889" ixy="-0.0" iyz="3e-06" ixz="0.0"/>
  </inertial>
  <visual>
    <origin xyz="0 0 0" rpy="0 0 0"/>
    <geometry>
      <mesh filename="package://AMR_description/meshes/base_link.stl" scale="0.001 0.001 0.001"/>
    </geometry>
    <material name="silver"/>
  </visual>
  <collision>
    <origin xyz="0 0 0" rpy="0 0 0"/>
    <geometry>
      <mesh filename="package://AMR_description/meshes/base_link.stl" scale="0.001 0.001 0.001"/>
    </geometry>
  </collision>
</link>

<link name="wheel_lf_1">
  <inertial>
    <origin xyz="0.004999938065343601 -7.229582901779885e-08 -4.7475483102785154e-07" rpy="0 0 0"/>
    <mass value="0.0554883802440297"/>
    <inertia ixx="6e-06" iyy="4e-06" izz="4e-06" ixy="0.0" iyz="0.0" ixz="0.0"/>
  </inertial>
  <visual>
    <origin xyz="-0.051477 -0.075216 -0.022215" rpy="0 0 0"/>
    <geometry>
      <mesh filename="package://AMR_description/meshes/wheel_lf_1.stl" scale="0.001 0.001 0.001"/>
    </geometry>
    <material name="silver"/>
  </visual>
  <collision>
    <origin xyz="-0.051477 -0.075216 -0.022215" rpy="0 0 0"/>
    <geometry>
      <mesh filename="package://AMR_description/meshes/wheel_lf_1.stl" scale="0.001 0.001 0.001"/>
    </geometry>
  </collision>
</link>

<link name="wheel_rf_1">
  <inertial>
    <origin xyz="-0.0050000619346564044 -7.229582901779885e-08 -4.74754831031321e-07" rpy="0 0 0"/>
    <mass value="0.05548838024402973"/>
    <inertia ixx="6e-06" iyy="4e-06" izz="4e-06" ixy="-0.0" iyz="0.0" ixz="-0.0"/>
  </inertial>
  <visual>
    <origin xyz="0.013523 -0.075216 -0.022215" rpy="0 0 0"/>
    <geometry>
      <mesh filename="package://AMR_description/meshes/wheel_rf_1.stl" scale="0.001 0.001 0.001"/>
    </geometry>
    <material name="silver"/>
  </visual>
  <collision>
    <origin xyz="0.013523 -0.075216 -0.022215" rpy="0 0 0"/>
    <geometry>
      <mesh filename="package://AMR_description/meshes/wheel_rf_1.stl" scale="0.001 0.001 0.001"/>
    </geometry>
  </collision>
</link>

<link name="wheel_lb_1">
  <inertial>
    <origin xyz="0.004999938065343601 -7.229582901779885e-08 -4.7475483102785154e-07" rpy="0 0 0"/>
    <mass value="0.0554883802440297"/>
    <inertia ixx="6e-06" iyy="4e-06" izz="4e-06" ixy="0.0" iyz="0.0" ixz="0.0"/>
  </inertial>
  <visual>
    <origin xyz="-0.051477 -0.025216 -0.022215" rpy="0 0 0"/>
    <geometry>
      <mesh filename="package://AMR_description/meshes/wheel_lb_1.stl" scale="0.001 0.001 0.001"/>
    </geometry>
    <material name="silver"/>
  </visual>
  <collision>
    <origin xyz="-0.051477 -0.025216 -0.022215" rpy="0 0 0"/>
    <geometry>
      <mesh filename="package://AMR_description/meshes/wheel_lb_1.stl" scale="0.001 0.001 0.001"/>
    </geometry>
  </collision>
</link>

<link name="wheel_rb_1">
  <inertial>
    <origin xyz="-0.0050000619346564044 -7.229582902473775e-08 -4.7475483103479044e-07" rpy="0 0 0"/>
    <mass value="0.05548838024402973"/>
    <inertia ixx="6e-06" iyy="4e-06" izz="4e-06" ixy="0.0" iyz="0.0" ixz="-0.0"/>
  </inertial>
  <visual>
    <origin xyz="0.013523 -0.025216 -0.022215" rpy="0 0 0"/>
    <geometry>
      <mesh filename="package://AMR_description/meshes/wheel_rb_1.stl" scale="0.001 0.001 0.001"/>
    </geometry>
    <material name="silver"/>
  </visual>
  <collision>
    <origin xyz="0.013523 -0.025216 -0.022215" rpy="0 0 0"/>
    <geometry>
      <mesh filename="package://AMR_description/meshes/wheel_rb_1.stl" scale="0.001 0.001 0.001"/>
    </geometry>
  </collision>
</link>

<link name="lidar_1_1">
  <inertial>
    <origin xyz="2.513081011901175e-07 -7.229582900392106e-08 0.003499525245168972" rpy="0 0 0"/>
    <mass value="0.006214698587331331"/>
    <inertia ixx="0.0" iyy="0.0" izz="0.0" ixy="0.0" iyz="0.0" ixz="0.0"/>
  </inertial>
  <visual>
    <origin xyz="-0.019624 -0.107716 -0.020215" rpy="0 0 0"/>
    <geometry>
      <mesh filename="package://AMR_description/meshes/lidar_1_1.stl" scale="0.001 0.001 0.001"/>
    </geometry>
    <material name="silver"/>
  </visual>
  <collision>
    <origin xyz="-0.019624 -0.107716 -0.020215" rpy="0 0 0"/>
    <geometry>
      <mesh filename="package://AMR_description/meshes/lidar_1_1.stl" scale="0.001 0.001 0.001"/>
    </geometry>
  </collision>
</link>

<joint name="Rev1" type="continuous">
  <origin xyz="0.051477 0.075216 0.022215" rpy="0 0 0"/>
  <parent link="base_link"/>
  <child link="wheel_lf_1"/>
  <axis xyz="1.0 0.0 0.0"/>
</joint>

<joint name="Rev2" type="continuous">
  <origin xyz="-0.013523 0.075216 0.022215" rpy="0 0 0"/>
  <parent link="base_link"/>
  <child link="wheel_rf_1"/>
  <axis xyz="-1.0 0.0 0.0"/>
</joint>

<joint name="Rev3" type="continuous">
  <origin xyz="0.051477 0.025216 0.022215" rpy="0 0 0"/>
  <parent link="base_link"/>
  <child link="wheel_lb_1"/>
  <axis xyz="1.0 0.0 0.0"/>
</joint>

<joint name="Rev4" type="continuous">
  <origin xyz="-0.013523 0.025216 0.022215" rpy="0 0 0"/>
  <parent link="base_link"/>
  <child link="wheel_rb_1"/>
  <axis xyz="-1.0 0.0 0.0"/>
</joint>

<joint name="Rigid5" type="fixed">
  <origin xyz="0.019624 0.107716 0.020215" rpy="0 0 0"/>
  <parent link="base_link"/>
  <child link="lidar_1_1"/>
</joint>

</robot>
